2024-12-17 11:07:29,258 - GraphGeneration - INFO - Base path: C:\Dropbox\Development\Python\Python_InspectVault\Python_InspectVault\tests\test_data
2024-12-17 11:07:29,258 - GraphGeneration - INFO - ディレクトリが存在します: C:\Dropbox\Development\Python\Python_InspectVault\Python_InspectVault\tests\test_data\CSV
2024-12-17 11:07:29,259 - GraphGeneration - INFO - ディレクトリが存在します: C:\Dropbox\Development\Python\Python_InspectVault\Python_InspectVault\tests\test_data\CSV_LOG
2024-12-17 11:07:29,259 - GraphGeneration - INFO - ディレクトリが存在します: C:\Dropbox\Development\Python\Python_InspectVault\Python_InspectVault\tests\test_data\templates
2024-12-17 11:07:29,261 - GraphGeneration - INFO - ディレクトリが存在します: C:\Dropbox\Development\Python\Python_InspectVault\Python_InspectVault\tests\test_data\logs
2024-12-17 11:07:29,261 - GraphGeneration - INFO - グラフ生成プロセスを開始します
2024-12-17 11:07:29,261 - GraphGeneration - INFO - CSVインポートを開始
2024-12-17 11:07:30,155 - GraphGeneration - INFO - CSVピボット処理を開始
2024-12-17 11:07:30,162 - GraphGeneration - ERROR - 予期せぬエラーが発生しました: cannot import name 'main' from 'src.csvpivot' (C:\Dropbox\Development\Python\Python_InspectVault\Python_InspectVault\src\csvpivot.py)
Traceback (most recent call last):
  File "C:\Dropbox\Development\Python\Python_InspectVault\Python_InspectVault\main.py", line 60, in run_process
    from src.csvpivot import main as csv_pivot_main
ImportError: cannot import name 'main' from 'src.csvpivot' (C:\Dropbox\Development\Python\Python_InspectVault\Python_InspectVault\src\csvpivot.py)
