2024-12-17 10:35:44,140 - GraphGeneration - INFO - Base path: C:\Dropbox\Development\Python\Python_InspectVault\Python_InspectVault\tests\test_data
2024-12-17 10:35:44,141 - GraphGeneration - INFO - ディレクトリが存在します: C:\Dropbox\Development\Python\Python_InspectVault\Python_InspectVault\tests\test_data\CSV
2024-12-17 10:35:44,141 - GraphGeneration - INFO - ディレクトリが存在します: C:\Dropbox\Development\Python\Python_InspectVault\Python_InspectVault\tests\test_data\CSV_LOG
2024-12-17 10:35:44,141 - GraphGeneration - INFO - ディレクトリが存在します: C:\Dropbox\Development\Python\Python_InspectVault\Python_InspectVault\tests\test_data\templates
2024-12-17 10:35:44,142 - GraphGeneration - INFO - ディレクトリが存在します: C:\Dropbox\Development\Python\Python_InspectVault\Python_InspectVault\tests\test_data\logs
2024-12-17 10:35:44,142 - GraphGeneration - INFO - グラフ生成プロセスを開始します
2024-12-17 10:35:44,142 - GraphGeneration - INFO - CSVインポートを開始
2024-12-17 10:35:47,229 - GraphGeneration - ERROR - 予期せぬエラーが発生しました: cannot import name 'main' from 'src.csvimport' (C:\Dropbox\Development\Python\Python_InspectVault\Python_InspectVault\src\csvimport.py)
Traceback (most recent call last):
  File "C:\Dropbox\Development\Python\Python_InspectVault\Python_InspectVault\main.py", line 52, in run_process
    from src.csvimport import main as csv_import_main
ImportError: cannot import name 'main' from 'src.csvimport' (C:\Dropbox\Development\Python\Python_InspectVault\Python_InspectVault\src\csvimport.py)
